[2023-03-15T16:10:02.558+0000] {taskinstance.py:1165} INFO - Dependencies all met for <TaskInstance: 01_dag_test.read_from_db scheduled__2022-10-13T00:00:00+00:00 [queued]>
[2023-03-15T16:10:02.565+0000] {taskinstance.py:1165} INFO - Dependencies all met for <TaskInstance: 01_dag_test.read_from_db scheduled__2022-10-13T00:00:00+00:00 [queued]>
[2023-03-15T16:10:02.565+0000] {taskinstance.py:1362} INFO - 
--------------------------------------------------------------------------------
[2023-03-15T16:10:02.566+0000] {taskinstance.py:1363} INFO - Starting attempt 1 of 1
[2023-03-15T16:10:02.566+0000] {taskinstance.py:1364} INFO - 
--------------------------------------------------------------------------------
[2023-03-15T16:10:02.574+0000] {taskinstance.py:1383} INFO - Executing <Task(PostgresOperator): read_from_db> on 2022-10-13 00:00:00+00:00
[2023-03-15T16:10:02.579+0000] {standard_task_runner.py:55} INFO - Started process 1509 to run task
[2023-03-15T16:10:02.583+0000] {standard_task_runner.py:82} INFO - Running: ['***', 'tasks', 'run', '01_dag_test', 'read_from_db', 'scheduled__2022-10-13T00:00:00+00:00', '--job-id', '356', '--raw', '--subdir', 'DAGS_FOLDER/dag-test.py', '--cfg-path', '/tmp/tmpmk8n42v9']
[2023-03-15T16:10:02.585+0000] {standard_task_runner.py:83} INFO - Job 356: Subtask read_from_db
[2023-03-15T16:10:02.637+0000] {task_command.py:376} INFO - Running <TaskInstance: 01_dag_test.read_from_db scheduled__2022-10-13T00:00:00+00:00 [running]> on host f11e2626d663
[2023-03-15T16:10:02.686+0000] {taskinstance.py:1592} INFO - Exporting the following env vars:
AIRFLOW_CTX_DAG_OWNER=***
AIRFLOW_CTX_DAG_ID=01_dag_test
AIRFLOW_CTX_TASK_ID=read_from_db
AIRFLOW_CTX_EXECUTION_DATE=2022-10-13T00:00:00+00:00
AIRFLOW_CTX_TRY_NUMBER=1
AIRFLOW_CTX_DAG_RUN_ID=scheduled__2022-10-13T00:00:00+00:00
[2023-03-15T16:10:02.701+0000] {taskinstance.py:1851} ERROR - Task failed with exception
Traceback (most recent call last):
  File "/home/airflow/.local/lib/python3.7/site-packages/airflow/providers/postgres/operators/postgres.py", line 94, in execute
    self.hook.run(self.sql, self.autocommit, parameters=self.parameters)
  File "/home/airflow/.local/lib/python3.7/site-packages/airflow/providers/common/sql/hooks/sql.py", line 288, in run
    with closing(self.get_conn()) as conn:
  File "/home/airflow/.local/lib/python3.7/site-packages/airflow/providers/postgres/hooks/postgres.py", line 88, in get_conn
    conn = deepcopy(self.connection or self.get_connection(conn_id))
  File "/home/airflow/.local/lib/python3.7/site-packages/airflow/hooks/base.py", line 70, in get_connection
    conn = Connection.get_connection_from_secrets(conn_id)
  File "/home/airflow/.local/lib/python3.7/site-packages/airflow/models/connection.py", line 432, in get_connection_from_secrets
    raise AirflowNotFoundException(f"The conn_id `{conn_id}` isn't defined")
airflow.exceptions.AirflowNotFoundException: The conn_id `postgres_test` isn't defined
[2023-03-15T16:10:02.704+0000] {taskinstance.py:1406} INFO - Marking task as FAILED. dag_id=01_dag_test, task_id=read_from_db, execution_date=20221013T000000, start_date=20230315T161002, end_date=20230315T161002
[2023-03-15T16:10:02.710+0000] {standard_task_runner.py:105} ERROR - Failed to execute job 356 for task read_from_db (The conn_id `postgres_test` isn't defined; 1509)
[2023-03-15T16:10:02.755+0000] {local_task_job.py:164} INFO - Task exited with return code 1
[2023-03-15T16:10:02.769+0000] {local_task_job.py:273} INFO - 0 downstream tasks scheduled from follow-on schedule check
