[2023-03-15T16:12:54.115+0000] {taskinstance.py:1165} INFO - Dependencies all met for <TaskInstance: 01_dag_test.read_from_db scheduled__2023-02-24T00:00:00+00:00 [queued]>
[2023-03-15T16:12:54.191+0000] {taskinstance.py:1165} INFO - Dependencies all met for <TaskInstance: 01_dag_test.read_from_db scheduled__2023-02-24T00:00:00+00:00 [queued]>
[2023-03-15T16:12:54.195+0000] {taskinstance.py:1362} INFO - 
--------------------------------------------------------------------------------
[2023-03-15T16:12:54.196+0000] {taskinstance.py:1363} INFO - Starting attempt 1 of 1
[2023-03-15T16:12:54.199+0000] {taskinstance.py:1364} INFO - 
--------------------------------------------------------------------------------
[2023-03-15T16:12:54.282+0000] {taskinstance.py:1383} INFO - Executing <Task(PostgresOperator): read_from_db> on 2023-02-24 00:00:00+00:00
[2023-03-15T16:12:54.332+0000] {standard_task_runner.py:55} INFO - Started process 3667 to run task
[2023-03-15T16:12:54.358+0000] {standard_task_runner.py:82} INFO - Running: ['***', 'tasks', 'run', '01_dag_test', 'read_from_db', 'scheduled__2023-02-24T00:00:00+00:00', '--job-id', '1040', '--raw', '--subdir', 'DAGS_FOLDER/dag-test.py', '--cfg-path', '/tmp/tmpttvvtwo4']
[2023-03-15T16:12:54.377+0000] {standard_task_runner.py:83} INFO - Job 1040: Subtask read_from_db
[2023-03-15T16:12:54.688+0000] {task_command.py:376} INFO - Running <TaskInstance: 01_dag_test.read_from_db scheduled__2023-02-24T00:00:00+00:00 [running]> on host f11e2626d663
[2023-03-15T16:12:55.139+0000] {taskinstance.py:1592} INFO - Exporting the following env vars:
AIRFLOW_CTX_DAG_OWNER=***
AIRFLOW_CTX_DAG_ID=01_dag_test
AIRFLOW_CTX_TASK_ID=read_from_db
AIRFLOW_CTX_EXECUTION_DATE=2023-02-24T00:00:00+00:00
AIRFLOW_CTX_TRY_NUMBER=1
AIRFLOW_CTX_DAG_RUN_ID=scheduled__2023-02-24T00:00:00+00:00
[2023-03-15T16:12:55.239+0000] {taskinstance.py:1851} ERROR - Task failed with exception
Traceback (most recent call last):
  File "/home/airflow/.local/lib/python3.7/site-packages/airflow/providers/postgres/operators/postgres.py", line 94, in execute
    self.hook.run(self.sql, self.autocommit, parameters=self.parameters)
  File "/home/airflow/.local/lib/python3.7/site-packages/airflow/providers/common/sql/hooks/sql.py", line 288, in run
    with closing(self.get_conn()) as conn:
  File "/home/airflow/.local/lib/python3.7/site-packages/airflow/providers/postgres/hooks/postgres.py", line 88, in get_conn
    conn = deepcopy(self.connection or self.get_connection(conn_id))
  File "/home/airflow/.local/lib/python3.7/site-packages/airflow/hooks/base.py", line 70, in get_connection
    conn = Connection.get_connection_from_secrets(conn_id)
  File "/home/airflow/.local/lib/python3.7/site-packages/airflow/models/connection.py", line 432, in get_connection_from_secrets
    raise AirflowNotFoundException(f"The conn_id `{conn_id}` isn't defined")
airflow.exceptions.AirflowNotFoundException: The conn_id `postgres_test` isn't defined
[2023-03-15T16:12:55.245+0000] {taskinstance.py:1406} INFO - Marking task as FAILED. dag_id=01_dag_test, task_id=read_from_db, execution_date=20230224T000000, start_date=20230315T161254, end_date=20230315T161255
[2023-03-15T16:12:55.277+0000] {standard_task_runner.py:105} ERROR - Failed to execute job 1040 for task read_from_db (The conn_id `postgres_test` isn't defined; 3667)
[2023-03-15T16:12:55.470+0000] {local_task_job.py:164} INFO - Task exited with return code 1
[2023-03-15T16:12:55.513+0000] {local_task_job.py:273} INFO - 0 downstream tasks scheduled from follow-on schedule check
