[2023-03-15T16:13:07.925+0000] {taskinstance.py:1165} INFO - Dependencies all met for <TaskInstance: 01_dag_test.read_from_db scheduled__2023-03-07T00:00:00+00:00 [queued]>
[2023-03-15T16:13:07.949+0000] {taskinstance.py:1165} INFO - Dependencies all met for <TaskInstance: 01_dag_test.read_from_db scheduled__2023-03-07T00:00:00+00:00 [queued]>
[2023-03-15T16:13:07.950+0000] {taskinstance.py:1362} INFO - 
--------------------------------------------------------------------------------
[2023-03-15T16:13:07.951+0000] {taskinstance.py:1363} INFO - Starting attempt 1 of 1
[2023-03-15T16:13:07.952+0000] {taskinstance.py:1364} INFO - 
--------------------------------------------------------------------------------
[2023-03-15T16:13:07.998+0000] {taskinstance.py:1383} INFO - Executing <Task(PostgresOperator): read_from_db> on 2023-03-07 00:00:00+00:00
[2023-03-15T16:13:08.014+0000] {standard_task_runner.py:55} INFO - Started process 3839 to run task
[2023-03-15T16:13:08.028+0000] {standard_task_runner.py:82} INFO - Running: ['***', 'tasks', 'run', '01_dag_test', 'read_from_db', 'scheduled__2023-03-07T00:00:00+00:00', '--job-id', '1093', '--raw', '--subdir', 'DAGS_FOLDER/dag-test.py', '--cfg-path', '/tmp/tmpst0se20e']
[2023-03-15T16:13:08.034+0000] {standard_task_runner.py:83} INFO - Job 1093: Subtask read_from_db
[2023-03-15T16:13:08.173+0000] {task_command.py:376} INFO - Running <TaskInstance: 01_dag_test.read_from_db scheduled__2023-03-07T00:00:00+00:00 [running]> on host f11e2626d663
[2023-03-15T16:13:08.329+0000] {taskinstance.py:1592} INFO - Exporting the following env vars:
AIRFLOW_CTX_DAG_OWNER=***
AIRFLOW_CTX_DAG_ID=01_dag_test
AIRFLOW_CTX_TASK_ID=read_from_db
AIRFLOW_CTX_EXECUTION_DATE=2023-03-07T00:00:00+00:00
AIRFLOW_CTX_TRY_NUMBER=1
AIRFLOW_CTX_DAG_RUN_ID=scheduled__2023-03-07T00:00:00+00:00
[2023-03-15T16:13:08.387+0000] {taskinstance.py:1851} ERROR - Task failed with exception
Traceback (most recent call last):
  File "/home/airflow/.local/lib/python3.7/site-packages/airflow/providers/postgres/operators/postgres.py", line 94, in execute
    self.hook.run(self.sql, self.autocommit, parameters=self.parameters)
  File "/home/airflow/.local/lib/python3.7/site-packages/airflow/providers/common/sql/hooks/sql.py", line 288, in run
    with closing(self.get_conn()) as conn:
  File "/home/airflow/.local/lib/python3.7/site-packages/airflow/providers/postgres/hooks/postgres.py", line 88, in get_conn
    conn = deepcopy(self.connection or self.get_connection(conn_id))
  File "/home/airflow/.local/lib/python3.7/site-packages/airflow/hooks/base.py", line 70, in get_connection
    conn = Connection.get_connection_from_secrets(conn_id)
  File "/home/airflow/.local/lib/python3.7/site-packages/airflow/models/connection.py", line 432, in get_connection_from_secrets
    raise AirflowNotFoundException(f"The conn_id `{conn_id}` isn't defined")
airflow.exceptions.AirflowNotFoundException: The conn_id `postgres_test` isn't defined
[2023-03-15T16:13:08.391+0000] {taskinstance.py:1406} INFO - Marking task as FAILED. dag_id=01_dag_test, task_id=read_from_db, execution_date=20230307T000000, start_date=20230315T161307, end_date=20230315T161308
[2023-03-15T16:13:08.418+0000] {standard_task_runner.py:105} ERROR - Failed to execute job 1093 for task read_from_db (The conn_id `postgres_test` isn't defined; 3839)
[2023-03-15T16:13:08.500+0000] {local_task_job.py:164} INFO - Task exited with return code 1
[2023-03-15T16:13:08.559+0000] {local_task_job.py:273} INFO - 0 downstream tasks scheduled from follow-on schedule check
